[2024-08-31T02:30:31.563+0000] {local_task_job_runner.py:120} INFO - ::group::Pre task execution logs
[2024-08-31T02:30:31.578+0000] {taskinstance.py:2076} INFO - Dependencies all met for dep_context=non-requeueable deps ti=<TaskInstance: etl_single_task_process_files.process_and_transform_files manual__2024-08-31T02:30:30.277280+00:00 [queued]>
[2024-08-31T02:30:31.587+0000] {taskinstance.py:2076} INFO - Dependencies all met for dep_context=requeueable deps ti=<TaskInstance: etl_single_task_process_files.process_and_transform_files manual__2024-08-31T02:30:30.277280+00:00 [queued]>
[2024-08-31T02:30:31.588+0000] {taskinstance.py:2306} INFO - Starting attempt 1 of 2
[2024-08-31T02:30:31.601+0000] {taskinstance.py:2330} INFO - Executing <Task(PythonOperator): process_and_transform_files> on 2024-08-31 02:30:30.277280+00:00
[2024-08-31T02:30:31.608+0000] {warnings.py:112} WARNING - /home/***/.local/lib/python3.12/site-packages/***/task/task_runner/standard_task_runner.py:61: DeprecationWarning: This process (pid=821) is multi-threaded, use of fork() may lead to deadlocks in the child.
  pid = os.fork()

[2024-08-31T02:30:31.609+0000] {standard_task_runner.py:63} INFO - Started process 823 to run task
[2024-08-31T02:30:31.609+0000] {standard_task_runner.py:90} INFO - Running: ['***', 'tasks', 'run', 'etl_single_task_process_files', 'process_and_transform_files', 'manual__2024-08-31T02:30:30.277280+00:00', '--job-id', '451', '--raw', '--subdir', 'DAGS_FOLDER/etl_pipeline.py', '--cfg-path', '/tmp/tmpsk91mczx']
[2024-08-31T02:30:31.612+0000] {standard_task_runner.py:91} INFO - Job 451: Subtask process_and_transform_files
[2024-08-31T02:30:31.647+0000] {task_command.py:426} INFO - Running <TaskInstance: etl_single_task_process_files.process_and_transform_files manual__2024-08-31T02:30:30.277280+00:00 [running]> on host 0fffd72ba499
[2024-08-31T02:30:31.727+0000] {taskinstance.py:2648} INFO - Exporting env vars: AIRFLOW_CTX_DAG_OWNER='***' AIRFLOW_CTX_DAG_ID='etl_single_task_process_files' AIRFLOW_CTX_TASK_ID='process_and_transform_files' AIRFLOW_CTX_EXECUTION_DATE='2024-08-31T02:30:30.277280+00:00' AIRFLOW_CTX_TRY_NUMBER='1' AIRFLOW_CTX_DAG_RUN_ID='manual__2024-08-31T02:30:30.277280+00:00'
[2024-08-31T02:30:31.728+0000] {taskinstance.py:430} INFO - ::endgroup::
[2024-08-31T02:30:31.749+0000] {base.py:84} INFO - Using connection ID 'zillow-aws' for task execution.
[2024-08-31T02:30:31.750+0000] {connection_wrapper.py:384} INFO - AWS Connection (conn_id='zillow-aws', conn_type='aws') credentials retrieved from login and password.
[2024-08-31T02:30:32.484+0000] {taskinstance.py:441} INFO - ::group::Post task execution logs
[2024-08-31T02:30:32.485+0000] {taskinstance.py:2905} ERROR - Task failed with exception
Traceback (most recent call last):
  File "/home/airflow/.local/lib/python3.12/site-packages/airflow/models/taskinstance.py", line 465, in _execute_task
    result = _execute_callable(context=context, **execute_callable_kwargs)
             ^^^^^^^^^^^^^^^^^^^^^^^^^^^^^^^^^^^^^^^^^^^^^^^^^^^^^^^^^^^^^
  File "/home/airflow/.local/lib/python3.12/site-packages/airflow/models/taskinstance.py", line 432, in _execute_callable
    return execute_callable(context=context, **execute_callable_kwargs)
           ^^^^^^^^^^^^^^^^^^^^^^^^^^^^^^^^^^^^^^^^^^^^^^^^^^^^^^^^^^^^
  File "/home/airflow/.local/lib/python3.12/site-packages/airflow/models/baseoperator.py", line 401, in wrapper
    return func(self, *args, **kwargs)
           ^^^^^^^^^^^^^^^^^^^^^^^^^^^
  File "/home/airflow/.local/lib/python3.12/site-packages/airflow/operators/python.py", line 235, in execute
    return_value = self.execute_callable()
                   ^^^^^^^^^^^^^^^^^^^^^^^
  File "/home/airflow/.local/lib/python3.12/site-packages/airflow/operators/python.py", line 252, in execute_callable
    return self.python_callable(*self.op_args, **self.op_kwargs)
           ^^^^^^^^^^^^^^^^^^^^^^^^^^^^^^^^^^^^^^^^^^^^^^^^^^^^^
  File "/opt/airflow/dags/src/utils.py", line 14, in process_and_transform_files
    response = s3.list_objects_v2(Bucket=bucket_name)
               ^^^^^^^^^^^^^^^^^^^^^^^^^^^^^^^^^^^^^^
  File "/home/airflow/.local/lib/python3.12/site-packages/botocore/client.py", line 565, in _api_call
    return self._make_api_call(operation_name, kwargs)
           ^^^^^^^^^^^^^^^^^^^^^^^^^^^^^^^^^^^^^^^^^^^
  File "/home/airflow/.local/lib/python3.12/site-packages/botocore/client.py", line 1021, in _make_api_call
    raise error_class(parsed_response, operation_name)
botocore.errorfactory.NoSuchBucket: An error occurred (NoSuchBucket) when calling the ListObjectsV2 operation: The specified bucket does not exist
[2024-08-31T02:30:32.493+0000] {taskinstance.py:1206} INFO - Marking task as UP_FOR_RETRY. dag_id=etl_single_task_process_files, task_id=process_and_transform_files, run_id=manual__2024-08-31T02:30:30.277280+00:00, execution_date=20240831T023030, start_date=20240831T023031, end_date=20240831T023032
[2024-08-31T02:30:32.514+0000] {standard_task_runner.py:110} ERROR - Failed to execute job 451 for task process_and_transform_files (An error occurred (NoSuchBucket) when calling the ListObjectsV2 operation: The specified bucket does not exist; 823)
[2024-08-31T02:30:32.547+0000] {local_task_job_runner.py:240} INFO - Task exited with return code 1
[2024-08-31T02:30:32.565+0000] {taskinstance.py:3503} INFO - 0 downstream tasks scheduled from follow-on schedule check
[2024-08-31T02:30:32.567+0000] {local_task_job_runner.py:222} INFO - ::endgroup::
